Workbook

Sheet Cronograma
A1: Cronograma - App de gestión de inventario para un pequeño negocio de tecnología
A3: Fecha de inicio | B3: 46272
G4: ="S"&INT((G6-($B$3-WEEKDAY($B$3)+1))/7)+1 -> S1 | H4: =IF(INT((H6-($B$3-WEEKDAY($B$3)+1))/7)+1<>INT((G6-($B$3-WEEKDAY($B$3)+1))/7)+1,"S"&INT((H6-($B$3-WEEKDAY($B$3)+1))/7)+1,"") | I4: =IF(INT((I6-($B$3-WEEKDAY($B$3)+1))/7)+1<>INT((H6-($B$3-WEEKDAY($B$3)+1))/7)+1,"S"&INT((I6-($B$3-WEEKDAY($B$3)+1))/7)+1,"") | J4: =IF(INT((J6-($B$3-WEEKDAY($B$3)+1))/7)+1<>INT((I6-($B$3-WEEKDAY($B$3)+1))/7)+1,"S"&INT((J6-($B$3-WEEKDAY($B$3)+1))/7)+1,"") | K4: =IF(INT((K6-($B$3-WEEKDAY($B$3)+1))/7)+1<>INT((J6-($B$3-WEEKDAY($B$3)+1))/7)+1,"S"&INT((K6-($B$3-WEEKDAY($B$3)+1))/7)+1,"") | L4: =IF(INT((L6-($B$3-WEEKDAY($B$3)+1))/7)+1<>INT((K6-($B$3-WEEKDAY($B$3)+1))/7)+1,"S"&INT((L6-($B$3-WEEKDAY($B$3)+1))/7)+1,"") -> S2 | M4: =IF(INT((M6-($B$3-WEEKDAY($B$3)+1))/7)+1<>INT((L6-($B$3-WEEKDAY($B$3)+1))/7)+1,"S"&INT((M6-($B$3-WEEKDAY($B$3)+1))/7)+1,"") | N4: =IF(INT((N6-($B$3-WEEKDAY($B$3)+1))/7)+1<>INT((M6-($B$3-WEEKDAY($B$3)+1))/7)+1,"S"&INT((N6-($B$3-WEEKDAY($B$3)+1))/7)+1,"") | O4: =IF(INT((O6-($B$3-WEEKDAY($B$3)+1))/7)+1<>INT((N6-($B$3-WEEKDAY($B$3)+1))/7)+1,"S"&INT((O6-($B$3-WEEKDAY($B$3)+1))/7)+1,"") | ... BC4: =IF(INT((BC6-($B$3-WEEKDAY($B$3)+1))/7)+1<>INT((BB6-($B$3-WEEKDAY($B$3)+1))/7)+1,"S"&INT((BC6-($B$3-WEEKDAY($B$3)+1))/7)+1,"") -> S11
G5: =CHOOSE(MONTH(G6),"ENE","FEB","MAR","ABR","MAY","JUN","JUL","AGO","SEP","OCT","NOV","DIC") -> SEP | H5: =IF(OR(H6=$G$6,MONTH(H6)<>MONTH(G6)),CHOOSE(MONTH(H6),"ENE","FEB","MAR","ABR","MAY","JUN","JUL","AGO","SEP","OCT","NOV","DIC"),"") | I5: =IF(OR(I6=$G$6,MONTH(I6)<>MONTH(H6)),CHOOSE(MONTH(I6),"ENE","FEB","MAR","ABR","MAY","JUN","JUL","AGO","SEP","OCT","NOV","DIC"),"") | J5: =IF(OR(J6=$G$6,MONTH(J6)<>MONTH(I6)),CHOOSE(MONTH(J6),"ENE","FEB","MAR","ABR","MAY","JUN","JUL","AGO","SEP","OCT","NOV","DIC"),"") | K5: =IF(OR(K6=$G$6,MONTH(K6)<>MONTH(J6)),CHOOSE(MONTH(K6),"ENE","FEB","MAR","ABR","MAY","JUN","JUL","AGO","SEP","OCT","NOV","DIC"),"") | L5: =IF(OR(L6=$G$6,MONTH(L6)<>MONTH(K6)),CHOOSE(MONTH(L6),"ENE","FEB","MAR","ABR","MAY","JUN","JUL","AGO","SEP","OCT","NOV","DIC"),"") | M5: =IF(OR(M6=$G$6,MONTH(M6)<>MONTH(L6)),CHOOSE(MONTH(M6),"ENE","FEB","MAR","ABR","MAY","JUN","JUL","AGO","SEP","OCT","NOV","DIC"),"") | N5: =IF(OR(N6=$G$6,MONTH(N6)<>MONTH(M6)),CHOOSE(MONTH(N6),"ENE","FEB","MAR","ABR","MAY","JUN","JUL","AGO","SEP","OCT","NOV","DIC"),"") | O5: =IF(OR(O6=$G$6,MONTH(O6)<>MONTH(N6)),CHOOSE(MONTH(O6),"ENE","FEB","MAR","ABR","MAY","JUN","JUL","AGO","SEP","OCT","NOV","DIC"),"") | ... BC5: =IF(OR(BC6=$G$6,MONTH(BC6)<>MONTH(BB6)),CHOOSE(MONTH(BC6),"ENE","FEB","MAR","ABR","MAY","JUN","JUL","AGO","SEP","OCT","NOV","DIC"),"")
A6: Actividad | B6: Issue | C6: Días | D6: Inicio | E6: Fin | F6: Sprint | G6: =WORKDAY($B$3-1,1,Festivos!$A$2:$A$20) -> 46272 | H6: =WORKDAY(G6,1,Festivos!$A$2:$A$20) -> 46273 | I6: =WORKDAY(H6,1,Festivos!$A$2:$A$20) -> 46274 | J6: =WORKDAY(I6,1,Festivos!$A$2:$A$20) -> 46275 | K6: =WORKDAY(J6,1,Festivos!$A$2:$A$20) -> 46276 | L6: =WORKDAY(K6,1,Festivos!$A$2:$A$20) -> 46279 | M6: =WORKDAY(L6,1,Festivos!$A$2:$A$20) -> 46280 | N6: =WORKDAY(M6,1,Festivos!$A$2:$A$20) -> 46281 | O6: =WORKDAY(N6,1,Festivos!$A$2:$A$20) -> 46282 | ... BC6: =WORKDAY(BB6,1,Festivos!$A$2:$A$20) -> 46343
G7: =MID("DLMXJVS",WEEKDAY(G6),1) -> L | H7: =MID("DLMXJVS",WEEKDAY(H6),1) -> M | I7: =MID("DLMXJVS",WEEKDAY(I6),1) -> X | J7: =MID("DLMXJVS",WEEKDAY(J6),1) -> J | K7: =MID("DLMXJVS",WEEKDAY(K6),1) -> V | L7: =MID("DLMXJVS",WEEKDAY(L6),1) -> L | M7: =MID("DLMXJVS",WEEKDAY(M6),1) -> M | N7: =MID("DLMXJVS",WEEKDAY(N6),1) -> X | ... BC7: =MID("DLMXJVS",WEEKDAY(BC6),1) -> M
A8: Labores previas
A9: Levantamiento de requerimientos (entrevista al cliente) | C9: 4 | D9: =WORKDAY($B$3-1,1,Festivos!$A$2:$A$20) -> 46272 | E9: =WORKDAY(D9,C9-1,Festivos!$A$2:$A$20) -> 46275 | F9: ="S"&(INT((D9-($B$3-WEEKDAY($B$3)+1))/7)+1) -> S1
A10: Crear épicas y tareas en GitHub Projects | C10: 1 | D10: =WORKDAY(E9,1,Festivos!$A$2:$A$20) -> 46276 | E10: =WORKDAY(D10,C10-1,Festivos!$A$2:$A$20) -> 46276 | F10: ="S"&(INT((D10-($B$3-WEEKDAY($B$3)+1))/7)+1) -> S1
A11: Diseño de la base de datos (colecciones y campos) | C11: 5 | D11: =WORKDAY(E10,1,Festivos!$A$2:$A$20) -> 46279 | E11: =WORKDAY(D11,C11-1,Festivos!$A$2:$A$20) -> 46283 | F11: ="S"&(INT((D11-($B$3-WEEKDAY($B$3)+1))/7)+1) -> S2
A12: Implementar la base de datos en Firebase | C12: 5 | D12: =WORKDAY(E11,1,Festivos!$A$2:$A$20) -> 46286 | E12: =WORKDAY(D12,C12-1,Festivos!$A$2:$A$20) -> 46290 | F12: ="S"&(INT((D12-($B$3-WEEKDAY($B$3)+1))/7)+1) -> S3
A13: Fin Labores Previas | C13: 0 | D13: =MAX(E9:E12) -> 46290 | E13: =D13 -> 46290 | F13: ="S"&(INT((D13-($B$3-WEEKDAY($B$3)+1))/7)+1) -> S3
A14: Épica 0 - Inicio de sesión y gestión de usuarios | B14: #51
A15: Arquitectura, proyecto Android y prototipo de pantallas | C15: 2 | D15: =WORKDAY(E13,1,Festivos!$A$2:$A$20) -> 46293 | E15: =WORKDAY(D15,C15-1,Festivos!$A$2:$A$20) -> 46294 | F15: ="S"&(INT((D15-($B$3-WEEKDAY($B$3)+1))/7)+1) -> S4
A16: Tarea 15 - Iniciar sesión (Login) | B16: #53 | C16: 2 | D16: =WORKDAY(E15,1,Festivos!$A$2:$A$20) -> 46295 | E16: =WORKDAY(D16,C16-1,Festivos!$A$2:$A$20) -> 46296 | F16: ="S"&(INT((D16-($B$3-WEEKDAY($B$3)+1))/7)+1) -> S4
A17: Tarea 16 - Cerrar sesión (Logout) | B17: #54 | C17: 1 | D17: =WORKDAY(E16,1,Festivos!$A$2:$A$20) -> 46297 | E17: =WORKDAY(D17,C17-1,Festivos!$A$2:$A$20) -> 46297 | F17: ="S"&(INT((D17-($B$3-WEEKDAY($B$3)+1))/7)+1) -> S4
A18: Tarea 17 - Recuperar y restablecer contraseña | B18: #55 | C18: 2 | D18: =WORKDAY(E17,1,Festivos!$A$2:$A$20) -> 46300 | E18: =WORKDAY(D18,C18-1,Festivos!$A$2:$A$20) -> 46301 | F18: ="S"&(INT((D18-($B$3-WEEKDAY($B$3)+1))/7)+1) -> S5
A19: Tarea 18 - Listar, activar o desactivar usuarios | B19: #56 | C19: 2 | D19: =D18 -> 46300 | E19: =WORKDAY(D19,C19-1,Festivos!$A$2:$A$20) -> 46301 | F19: ="S"&(INT((D19-($B$3-WEEKDAY($B$3)+1))/7)+1) -> S5
A20: Fin Épica 0 | C20: 0 | D20: =MAX(E15:E19) -> 46301 | E20: =D20 -> 46301 | F20: ="S"&(INT((D20-($B$3-WEEKDAY($B$3)+1))/7)+1) -> S5
A21: Épica 1 - Gestión de productos | B21: #30
A22: Tarea 01 - Registrar producto (código de barras, serial, proveedor) | B22: #31 | C22: 2 | D22: =WORKDAY(E20,1,Festivos!$A$2:$A$20) -> 46302 | E22: =WORKDAY(D22,C22-1,Festivos!$A$2:$A$20) -> 46303 | F22: ="S"&(INT((D22-($B$3-WEEKDAY($B$3)+1))/7)+1) -> S5
A23: Registrar y consultar proveedores | C23: 2 | D23: =D22 -> 46302 | E23: =WORKDAY(D23,C23-1,Festivos!$A$2:$A$20) -> 46303 | F23: ="S"&(INT((D23-($B$3-WEEKDAY($B$3)+1))/7)+1) -> S5
A24: Tarea 02 - Consultar productos | B24: #32 | C24: 1 | D24: =WORKDAY(E23,1,Festivos!$A$2:$A$20) -> 46304 | E24: =WORKDAY(D24,C24-1,Festivos!$A$2:$A$20) -> 46304 | F24: ="S"&(INT((D24-($B$3-WEEKDAY($B$3)+1))/7)+1) -> S5
A25: Tarea 03 - Buscar producto (nombre o código de barras con cámara) | B25: #33 | C25: 2 | D25: =WORKDAY(E24,1,Festivos!$A$2:$A$20) -> 46308 | E25: =WORKDAY(D25,C25-1,Festivos!$A$2:$A$20) -> 46309 | F25: ="S"&(INT((D25-($B$3-WEEKDAY($B$3)+1))/7)+1) -> S6
A26: Tarea 04 - Actualizar producto | B26: #34 | C26: 1 | D26: =WORKDAY(E25,1,Festivos!$A$2:$A$20) -> 46310 | E26: =WORKDAY(D26,C26-1,Festivos!$A$2:$A$20) -> 46310 | F26: ="S"&(INT((D26-($B$3-WEEKDAY($B$3)+1))/7)+1) -> S6
A27: Tarea 05 - Eliminar producto | B27: #35 | C27: 1 | D27: =D26 -> 46310 | E27: =WORKDAY(D27,C27-1,Festivos!$A$2:$A$20) -> 46310 | F27: ="S"&(INT((D27-($B$3-WEEKDAY($B$3)+1))/7)+1) -> S6
A28: Fin Épica 1 | C28: 0 | D28: =MAX(E22:E27) -> 46310 | E28: =D28 -> 46310 | F28: ="S"&(INT((D28-($B$3-WEEKDAY($B$3)+1))/7)+1) -> S6
A29: Épica 2 - Control de inventario | B29: #36
A30: Tarea 06 - Consultar stock actual | B30: #37 | C30: 1 | D30: =WORKDAY(E28,1,Festivos!$A$2:$A$20) -> 46311 | E30: =WORKDAY(D30,C30-1,Festivos!$A$2:$A$20) -> 46311 | F30: ="S"&(INT((D30-($B$3-WEEKDAY($B$3)+1))/7)+1) -> S6
A31: Tarea 07 - Registrar entrada (seriales, proveedor, fecha) | B31: #39 | C31: 2 | D31: =WORKDAY(E30,1,Festivos!$A$2:$A$20) -> 46314 | E31: =WORKDAY(D31,C31-1,Festivos!$A$2:$A$20) -> 46315 | F31: ="S"&(INT((D31-($B$3-WEEKDAY($B$3)+1))/7)+1) -> S7
A32: Tarea 08 - Consultar historial de movimientos | B32: #40 | C32: 1 | D32: =WORKDAY(E31,1,Festivos!$A$2:$A$20) -> 46316 | E32: =WORKDAY(D32,C32-1,Festivos!$A$2:$A$20) -> 46316 | F32: ="S"&(INT((D32-($B$3-WEEKDAY($B$3)+1))/7)+1) -> S7
A33: Fin Épica 2 | C33: 0 | D33: =MAX(E30:E32) -> 46316 | E33: =D33 -> 46316 | F33: ="S"&(INT((D33-($B$3-WEEKDAY($B$3)+1))/7)+1) -> S7
A34: Épica 3 - Gestión de ventas | B34: #41
A35: Tarea 09 - Registrar venta (escáner y seriales) | B35: #42 | C35: 2 | D35: =WORKDAY(E33,1,Festivos!$A$2:$A$20) -> 46317 | E35: =WORKDAY(D35,C35-1,Festivos!$A$2:$A$20) -> 46318 | F35: ="S"&(INT((D35-($B$3-WEEKDAY($B$3)+1))/7)+1) -> S7
A36: Tarea 10 - Descontar productos vendidos del inventario | B36: #43 | C36: 1 | D36: =WORKDAY(E35,1,Festivos!$A$2:$A$20) -> 46321 | E36: =WORKDAY(D36,C36-1,Festivos!$A$2:$A$20) -> 46321 | F36: ="S"&(INT((D36-($B$3-WEEKDAY($B$3)+1))/7)+1) -> S8
A37: Tarea 11 - Consultar productos vendidos | B37: #44 | C37: 1 | D37: =WORKDAY(E36,1,Festivos!$A$2:$A$20) -> 46322 | E37: =WORKDAY(D37,C37-1,Festivos!$A$2:$A$20) -> 46322 | F37: ="S"&(INT((D37-($B$3-WEEKDAY($B$3)+1))/7)+1) -> S8
A38: Fin Épica 3 | C38: 0 | D38: =MAX(E35:E37) -> 46322 | E38: =D38 -> 46322 | F38: ="S"&(INT((D38-($B$3-WEEKDAY($B$3)+1))/7)+1) -> S8
A39: Épica 4 - Alertas de stock | B39: #45
A40: Tarea 12 - Definir stock mínimo | B40: #46 | C40: 1 | D40: =WORKDAY(E38,1,Festivos!$A$2:$A$20) -> 46323 | E40: =WORKDAY(D40,C40-1,Festivos!$A$2:$A$20) -> 46323 | F40: ="S"&(INT((D40-($B$3-WEEKDAY($B$3)+1))/7)+1) -> S8
A41: Tarea 13 - Identificar productos con bajo stock | B41: #47 | C41: 1 | D41: =WORKDAY(E40,1,Festivos!$A$2:$A$20) -> 46324 | E41: =WORKDAY(D41,C41-1,Festivos!$A$2:$A$20) -> 46324 | F41: ="S"&(INT((D41-($B$3-WEEKDAY($B$3)+1))/7)+1) -> S8
...

Sheet Requerimientos
A1: Requerimientos del cliente y cómo los resuelve la app
A4: # | B4: Necesidad o problema del cliente | C4: Cómo lo resuelve la app | D4: Tareas | E4: Sprint
A5: 1 | B5: Dejar la hoja de cálculo: los registros manuales de entradas y salidas quedan mal. | C5: Formularios con campos obligatorios, lectura del código de barras con la cámara, código y serial únicos, stock que nunca queda negativo y cada cambio guardado con usuario y fecha. | D5: #31 #33 #39 #42 #43 | E5: S5 a S8
A6: 2 | B6: No hay alerta cuando se acaba el stock. | C6: Stock mínimo por producto, estado del stock recalculado en cada movimiento y alerta visible al abrir la app con productos bajos o agotados. | D6: #46 #47 #48 | E6: S8
A7: 3 | B7: Saber qué productos hay disponibles (visibilidad). | C7: Lista y buscador en tiempo real con el stock actual de cada producto y color según su estado. | D7: #32 #33 #37 | E7: S5 y S6
A8: 4 | B8: Saber qué productos se han vendido (control). | C8: Cada venta guarda productos, cantidades y seriales; consulta de vendidos por fechas. | D8: #42 #44 | E8: S7 y S8
A9: 5 | B9: Guardar serial, código de barras, nombre completo, proveedor, precio, fechas de entrada y salida y cantidades. | C9: Colecciones productos, proveedores, unidades (una por serial con fecha de entrada y salida) y movimientos. | D9: #31 #39 #43 | E9: S2 y S3
A10: 6 | B10: Todos operan el sistema, las 24 horas. | C10: Todos los usuarios activos registran productos, entradas y ventas; el administrador además gestiona usuarios. Firebase está en la nube y disponible todo el día. | D10: #53 a #56, reglas | E10: S4, S5 y S9
A11: 7 | B11: Uso híbrido (computador y dispositivos móviles). | C11: Los datos están en la nube y se sincronizan en tiempo real entre dispositivos. La app Android funciona en celular y en tablet de mostrador; Firebase permite agregar luego una versión web con la misma base de datos. | D11: Arquitectura | E11: S4
A12: 8 | B12: Reportes: cierre diario de ventas, valoración del inventario y productos más vendidos. | C12: Épica 6 nueva con los tres reportes. Se debe crear en GitHub porque no estaba en el tablero. | D12: Épica 6 | E12: S9 y S10
A13: 9 | B13: La cantidad de productos y la frecuencia de entradas varía. | C13: Firestore crece sin cambiar la estructura; listas paginadas y búsqueda por código o nombre. | D13: #32 #33 | E13: S5 y S6
A14: 10 | B14: Herramienta sencilla para el día a día. | C14: Pocas pantallas, escáner en lugar de escribir códigos y venta en pocos pasos. | D14: Prototipo | E14: S4

Sheet Sprints
A1: Avance por sprints (semanal) - App de gestión de inventario
A4: Sprint | B4: Desde | C4: Hasta | D4: Objetivo del sprint | E4: Tareas (issues GitHub) | F4: Paso a paso del desarrollo | G4: Entregable para mostrar al profesor | H4: Estado | I4: Evidencia
A5: Sprint 1 | B5: =MAX((Cronograma!$B$3-WEEKDAY(Cronograma!$B$3)+1)+0,Cronograma!$B$3) -> 46272 | C5: =MIN((Cronograma!$B$3-WEEKDAY(Cronograma!$B$3)+1)+6,Cronograma!$D$68) -> 46277 | D5: Levantamiento de requerimientos | E5: Entrevista al cliente Épicas 0 a 5 y Tareas 01 a 18 en GitHub Projects | F5: 1. Se analiza el caso: el dueño de la tienda de tecnología lleva el inventario en una hoja de cálculo y no sabe qué tiene disponible, qué se agota ni qué se vendió. 2. Entrevista al cliente sobre errores actuales, datos del producto, usuarios, dispositivos, reportes y volumen de productos. 3. Hallazgos: los registros manuales quedan mal, no hay alerta cuando se acaba el stock, se debe guardar serial, código de barras, proveedor, precio y fechas de entrada y salida, todos operan el sistema las 24 horas, el uso es híbrido y se necesitan reportes. 4. Se escriben las épicas y tareas en el tablero de GitHub Projects. | G5: Respuestas de la entrevista, hoja Requerimientos y tablero de GitHub. | H5: Terminado | I5: Tablero GitHub
A6: Sprint 2 | B6: =MAX((Cronograma!$B$3-WEEKDAY(Cronograma!$B$3)+1)+7,Cronograma!$B$3) -> 46278 | C6: =MIN((Cronograma!$B$3-WEEKDAY(Cronograma!$B$3)+1)+13,Cronograma!$D$68) -> 46284 | D6: Diseño de la base de datos | E6: Diseño de la base de datos (colecciones y campos) | F6: 1. Se elige Cloud Firestore (Firebase): está en la nube, disponible las 24 horas y sincroniza varios dispositivos a la vez. 2. Se definen las colecciones: usuarios, proveedores, categorias, productos, unidades (una por serial), movimientos, ventas, alertas y cierresDiarios. 3. Cada requerimiento de la entrevista queda cubierto por un campo: serial, código de barras, proveedor, precio de compra y venta, fecha de entrada y fecha de salida (hoja Base de datos). | G6: Modelo de datos con colecciones, campos y relaciones. | H6: En progreso | I6: Tablero GitHub
A7: Sprint 3 | B7: =MAX((Cronograma!$B$3-WEEKDAY(Cronograma!$B$3)+1)+14,Cronograma!$B$3) -> 46285 | C7: =MIN((Cronograma!$B$3-WEEKDAY(Cronograma!$B$3)+1)+20,Cronograma!$D$68) -> 46291 | D7: Implementación de la base de datos | E7: Implementar la base de datos en Firebase | F7: 1. Se crea el proyecto en la consola de Firebase y se activan Authentication y Firestore. 2. Se crean las colecciones con datos de prueba: productos reales de la tienda con serial y código de barras, proveedores y usuarios. 3. Se crea el primer usuario administrador. 4. Se configuran los índices para el historial, las ventas y los reportes. | G7: Consola de Firebase con las colecciones y datos de prueba. | H7: En progreso | I7: Tablero GitHub
A8: Sprint 4 | B8: =MAX((Cronograma!$B$3-WEEKDAY(Cronograma!$B$3)+1)+21,Cronograma!$B$3) -> 46292 | C8: =MIN((Cronograma!$B$3-WEEKDAY(Cronograma!$B$3)+1)+27,Cronograma!$D$68) -> 46298 | D8: Épica 0 - Login y logout | E8: Arquitectura y prototipo de pantallas #53 Tarea 15 - Iniciar sesión #54 Tarea 16 - Cerrar sesión | F8: 1. Se conecta la app Android (Kotlin y Jetpack Compose) con Firebase y se maquetan las pantallas pensando en uso sencillo desde celular o tablet en el mostrador. 2. Pantalla de login con validación de correo y contraseña. 3. Inicio de sesión con Firebase Auth y verificación de que el usuario esté activo. 4. Cierre de sesión, importante porque varias personas usan el mismo dispositivo en distintos turnos. | G8: Demo en vivo: entrar con un usuario de prueba y cerrar sesión. | H8: Pendiente | I8: Tablero GitHub
A9: Sprint 5 | B9: =MAX((Cronograma!$B$3-WEEKDAY(Cronograma!$B$3)+1)+28,Cronograma!$B$3) -> 46299 | C9: =MIN((Cronograma!$B$3-WEEKDAY(Cronograma!$B$3)+1)+34,Cronograma!$D$68) -> 46305 | D9: Épica 0 cierre e inicio de productos | E9: #55 Tarea 17 - Recuperar contraseña #56 Tarea 18 - Activar o desactivar usuarios #31 Tarea 01 - Registrar producto Registrar proveedores #32 Tarea 02 - Consultar productos | F9: 1. Recuperación de contraseña por correo. 2. Pantalla de administración para activar o desactivar usuarios. 3. Formulario de producto con código de barras, nombre completo, proveedor, precios, stock mínimo y si maneja serial. Todos los campos obligatorios se validan para evitar los errores de la hoja de cálculo. 4. Registro de proveedores y lista de productos en tiempo real. | G9: Demo: administrar usuarios, crear un proveedor y registrar un producto. Cierre de la Épica 0. | H9: Pendiente | I9: Tablero GitHub
A10: Sprint 6 | B10: =MAX((Cronograma!$B$3-WEEKDAY(Cronograma!$B$3)+1)+35,Cronograma!$B$3) -> 46306 | C10: =MIN((Cronograma!$B$3-WEEKDAY(Cronograma!$B$3)+1)+41,Cronograma!$D$68) -> 46312 | D10: Épica 1 - Búsqueda y edición | E10: #33 Tarea 03 - Buscar producto #34 Tarea 04 - Actualizar producto #35 Tarea 05 - Eliminar producto #37 Tarea 06 - Consultar stock actual | F10: 1. Buscador por nombre y lectura del código de barras con la cámara, para no escribir códigos a mano. 2. Edición del producto y eliminación lógica (activo = false) para no perder el historial. 3. Vista de stock actual con color según el estado: disponible, bajo o agotado. | G10: Demo: escanear un código de barras, editar un producto y ver el stock. Cierre de la Épica 1. | H10: Pendiente | I10: Tablero GitHub
A11: Sprint 7 | B11: =MAX((Cronograma!$B$3-WEEKDAY(Cronograma!$B$3)+1)+42,Cronograma!$B$3) -> 46313 | C11: =MIN((Cronograma!$B$3-WEEKDAY(Cronograma!$B$3)+1)+48,Cronograma!$D$68) -> 46319 | D11: Épica 2 - Entradas y ventas | E11: #39 Tarea 07 - Registrar entrada #40 Tarea 08 - Historial de movimientos #42 Tarea 09 - Registrar venta | F11: 1. Registro de entrada: se elige el proveedor, se escanean los seriales y el sistema guarda la fecha de entrada de cada unidad y suma el stock en una sola transacción. 2. Historial de movimientos por producto con fecha y usuario, para saber quién registró cada cambio. 3. Pantalla de venta: se escanea el producto o el serial y se calcula el total. | G11: Demo: registrar una entrada con seriales y ver el historial. Cierre de la Épica 2. | H11: Pendiente | I11: Tablero GitHub
A12: Sprint 8 | B12: =MAX((Cronograma!$B$3-WEEKDAY(Cronograma!$B$3)+1)+49,Cronograma!$B$3) -> 46320 | C12: =MIN((Cronograma!$B$3-WEEKDAY(Cronograma!$B$3)+1)+55,Cronograma!$D$68) -> 46326 | D12: Épica 3 cierre y Épica 4 - Alertas | E12: #43 Tarea 10 - Descontar productos vendidos #44 Tarea 11 - Consultar productos vendidos #46 Tarea 12 - Stock mínimo #47 Tarea 13 - Bajo stock #48 Tarea 14 - Alerta de agotado | F12: 1. Al confirmar la venta se valida el stock, se descuenta el inventario, se marca cada serial como vendido con su fecha de salida y se registra el movimiento. Si algo falla no se guarda nada. 2. Consulta de productos vendidos por fechas. 3. Stock mínimo por producto y recálculo automático del estado del stock. 4. Alerta visible al abrir la app con los productos en bajo stock o agotados, que resuelve el problema de quedarse sin mercancía sin aviso. | G12: Demo: vender hasta bajar del mínimo y ver la alerta. Cierre de las Épicas 3 y 4. | H12: Pendiente | I12: Tablero GitHub
A13: Sprint 9 | B13: =MAX((Cronograma!$B$3-WEEKDAY(Cronograma!$B$3)+1)+56,Cronograma!$B$3) -> 46327 | C13: =MIN((Cronograma!$B$3-WEEKDAY(Cronograma!$B$3)+1)+62,Cronograma!$D$68) -> 46333 | D13: Épica 5 - Seguridad e inicio de reportes | E13: #57 Tarea 15 - Iniciar sesión #58 Tarea 16 - Cerrar sesión #59 Iniciar sesión Reglas de seguridad de Firestore Cierre diario de ventas | F13: 1. Revisión del acceso: sesión persistente y cierre de sesión en todas las pantallas. 2. Publicación de las reglas de Firestore: todos los usuarios activos operan el sistema y solo el administrador gestiona usuarios y anula ventas. 3. Reporte de cierre diario: total vendido, número de ventas y unidades del día. | G13: Reglas publicadas y demo del cierre diario. Cierre de la Épica 5. | H13: Pendiente | I13: Tablero GitHub
A14: Sprint 10 | B14: =MAX((Cronograma!$B$3-WEEKDAY(Cronograma!$B$3)+1)+63,Cronograma!$B$3) -> 46334 | C14: =MIN((Cronograma!$B$3-WEEKDAY(Cronograma!$B$3)+1)+69,Cronograma!$D$68) -> 46340 | D14: Reportes, pruebas y documentación | E14: Valoración total del inventario Productos más vendidos Pruebas funcionales Corrección de errores Documentación y manual de usuario | F14: 1. Reporte de valoración del inventario (stock por precio de compra) y ranking de productos más vendidos. 2. Pruebas funcionales de cada módulo con los casos de la entrevista. 3. Corrección de errores. 4. Documentación técnica y manual de usuario con capturas. | G14: Demo de los tres reportes, resultados de pruebas y documentación. Cierre de la Épica 6. | H14: Pendiente | I14: Tablero GitHub
A15: Sprint 11 | B15: =MAX((Cronograma!$B$3-WEEKDAY(Cronograma!$B$3)+1)+70,Cronograma!$B$3) -> 46341 | C15: =MIN((Cronograma!$B$3-WEEKDAY(Cronograma!$B$3)+1)+76,Cronograma!$D$68) -> 46343 | D15: Entrega final | E15: Revisión final con el equipo Presentación y entrega al docente | F15: 1. Revisión final comparando la app con cada requerimiento de la hoja Requerimientos. 2. Entrega del APK, el repositorio y la documentación. 3. Presentación final al profesor. | G15: Presentación final con la app funcionando (martes 17 de noviembre). | H15: Pendiente | I15: Tablero GitHub
A17: Avance general (sprints terminados) | D17: =COUNTIF(H5:H15,"Terminado")/COUNTA(H5:H15) -> 0.090909091

Sheet Base de datos
A1: Base de datos - (Firebase)
A4: usuarios/{uid} — El id del documento es el uid de Firebase Authentication (#53 #54 #55 #56)
A5: Colección | B5: Campo | C5: Tipo | D5: Obligatorio | E5: Descripción | F5: Ejemplo | G5: Tarea relacionada
A6: usuarios | B6: uid | C6: string | D6: Sí | E6: Id del usuario en Firebase Auth | F6: Xk29aP...
A7: usuarios | B7: nombre | C7: string | D7: Sí | E7: Nombre completo | F7: Laura Gómez
A8: usuarios | B8: correo | C8: string | D8: Sí | E8: Correo con el que inicia sesión | F8: laura@tienda.com | G8: #53
A9: usuarios | B9: rol | C9: string | D9: Sí | E9: admin u operador. Todos operan el sistema; el admin además gestiona usuarios | F9: operador | G9: #56
A10: usuarios | B10: activo | C10: boolean | D10: Sí | E10: Si es false no puede entrar al sistema | F10: true | G10: #56
A11: usuarios | B11: fechaCreacion | C11: timestamp | D11: Sí | E11: Fecha de registro | F11: 07/09/2026 10:15
A12: usuarios | B12: ultimoAcceso | C12: timestamp | D12: No | E12: Último inicio de sesión | F12: 21/09/2026 08:02 | G12: #53
A14: proveedores/{id} — Proveedores de la mercancía (requerimiento de la entrevista) (#31 #39)
A15: Colección | B15: Campo | C15: Tipo | D15: Obligatorio | E15: Descripción | F15: Ejemplo | G15: Tarea relacionada
A16: proveedores | B16: nombre | C16: string | D16: Sí | E16: Razón social o nombre del proveedor | F16: Distribuidora TecnoAndina S.A.S.
A17: proveedores | B17: nit | C17: string | D17: Sí | E17: NIT o documento | F17: 901234567-8
A18: proveedores | B18: telefono | C18: string | D18: No | E18: Teléfono de contacto | F18: 604 444 1234
A19: proveedores | B19: correo | C19: string | D19: No | E19: Correo de contacto | F19: ventas@tecnoandina.com
A20: proveedores | B20: activo | C20: boolean | D20: Sí | E20: Si se muestra en los formularios | F20: true
A22: categorias/{id} — Agrupa los productos de la tienda (#31 #33)
A23: Colección | B23: Campo | C23: Tipo | D23: Obligatorio | E23: Descripción | F23: Ejemplo | G23: Tarea relacionada
A24: categorias | B24: nombre | C24: string | D24: Sí | E24: Nombre de la categoría | F24: Celulares
A25: categorias | B25: activa | C25: boolean | D25: Sí | E25: Si se muestra en los formularios | F25: true
A27: productos/{id} — Catálogo e inventario de la tienda (#31 a #37, #46 a #48)
A28: Colección | B28: Campo | C28: Tipo | D28: Obligatorio | E28: Descripción | F28: Ejemplo | G28: Tarea relacionada
A29: productos | B29: codigoBarras | C29: string | D29: Sí | E29: Código de barras del producto, único. Se lee con la cámara | F29: 7701234567890 | G29: #31 #33
A30: productos | B30: nombre | C30: string | D30: Sí | E30: Nombre completo del producto | F30: Samsung Galaxy A15 128 GB Negro | G30: #31
A31: productos | B31: nombreBusqueda | C31: string | D31: Sí | E31: Nombre en minúsculas y sin tildes para el buscador | F31: samsung galaxy a15 128 gb negro | G31: #33
A32: productos | B32: categoriaId | C32: string | D32: Sí | E32: Id del documento en categorias | F32: cat_celulares
A33: productos | B33: marca | C33: string | D33: No | E33: Marca | F33: Samsung
A34: productos | B34: proveedorId | C34: string | D34: Sí | E34: Proveedor principal (id en proveedores) | F34: prov_tecnoandina | G34: #31
A35: productos | B35: serializado | C35: boolean | D35: Sí | E35: true si cada unidad tiene número de serie o IMEI | F35: true | G35: #31
A36: productos | B36: precioCompra | C36: number | D36: Sí | E36: Costo unitario (COP) | F36: 650000
A37: productos | B37: precioVenta | C37: number | D37: Sí | E37: Precio de venta (COP) | F37: 799000
A38: productos | B38: stockActual | C38: number | D38: Sí | E38: Unidades disponibles. Nunca puede quedar negativo | F38: 12 | G38: #37
A39: productos | B39: stockMinimo | C39: number | D39: Sí | E39: Cantidad a partir de la cual se alerta | F39: 3 | G39: #46
A40: productos | B40: estadoStock | C40: string | D40: Sí | E40: OK, BAJO o AGOTADO. Se recalcula en cada movimiento | F40: OK | G40: #47 #48
A41: productos | B41: activo | C41: boolean | D41: Sí | E41: false = producto eliminado (eliminación lógica) | F41: true | G41: #35
A42: productos | B42: fechaCreacion | C42: timestamp | D42: Sí | E42: Fecha de registro | F42: 05/10/2026
A43: productos | B43: fechaActualizacion | C43: timestamp | D43: Sí | E43: Última modificación | F43: 13/10/2026 | G43: #34
A44: productos | B44: creadoPor | C44: string | D44: Sí | E44: uid del usuario que lo registró | F44: Xk29aP...
A46: unidades/{id} — Una unidad física por serial, con su fecha de entrada y de salida (#39 #42 #43)
...

Sheet Festivos
A1: Festivos Colombia (no se trabajan)
A2: 46307
A3: 46328
A4: 46342
A5: 46364
A6: 46381
